Workbook

Sheet Masterlist
A1: Custom reports - GSX KBB / KGBs Used
A2: Order id | B2: Location Name | C2: GSX Repair Number | D2: GSX Repair Strategy | E2: Current GSX Status | F2: Repair Closed Date | G2: Product Code | H2: Product Description | I2: Product KGB | J2: Product KBB
A3: 20062784 | B3: MOBILECARE - GLORIETTA 5 | C3: G712090089 | D3: CIN | E3: SPCM | F3: 46185 | G3: ZP661-28885 | H3: Silver, iPad 10th generation, 64GB, Wi-Fi, ITP | I3: K0MY6JLF4N | J3: DHGJ0NJ504
A4: 20056477 | B4: MOBILECARE - GLORIETTA 5 | C4: G709596193 | D4: CIN | E4: SPCM | F4: 46153 | G4: Z661-43102 | H4: AirPods 4, Right, CI/AR, CN, INT | I4: GN1HQB0837M0000B32
A5: 20055406 | B5: MOBILECARE - GLORIETTA 5 | C5: G708611607 | D5: CIN | E5: SPCM | F5: 46123 | G5: 661-36918 | H5: Battery, iPhone 15 Pro Max | I5: FG9HP7003DJ00006TT | J5: F5DGYK0033K00006TU
A6: 20054338 | B6: MOBILECARE - GLORIETTA 5 | C6: G690356932 | D6: CIN | E6: SPCM | F6: 46117 | G6: 661-56050 | H6: Display, iPhone 17 Pro Max | I6: GH3HPY00KQV0000MUZ | J6: GH3HKU01FNB0000MUZ
A7: 20047553 | B7: MOBILECARE - GLORIETTA 5 | C7: G705425629 | D7: CIN | E7: SPCM | F7: 46108 | G7: 661-40169 | H7: Logic Board, 8-core CPU, 8-core GPU, 8 GB, 256 GB | I7: C02HNC000010000FJV | J7: C02H8C00CKD0000FJV
A8: 20047553 | B8: MOBILECARE - GLORIETTA 5 | C8: G705425629 | D8: CIN | E8: SPCM | F8: 46108 | G8: 661-40218 | H8: Display, Silver | I8: GMG5454001X1J87AP | J8: F0Y427601VK1J87AV
A9: 20047612 | B9: MOBILECARE - GLORIETTA 5 | C9: G704607819 | D9: CIN | E9: SCOM | F9: 46087 | G9: Z661-35418 | H9: AirPods Pro 2nd gen USB-C, Case, CI/AR, INT | I9: M4C0WVDJK4 | J9: L29P2GM2JD
A10: 20036869 | B10: MOBILECARE - GLORIETTA 5 | C10: G702154797 | D10: CIN | E10: SPCM | F10: 46074 | G10: 661-16806 | H10: Display Assembly, Space Gray | I10: GMG544700XQNR89B1 | J10: GMG337402FBNR8DBP
A11: 20040047 | B11: MOBILECARE - GLORIETTA 5 | C11: G701291855 | D11: CIN | E11: SPCM | F11: 46058 | G11: 661-21991 | H11: Battery, iPhone 13 | I11: F8Y5506CF3B18FKBW | J11: FG914160ZF518FN58
A12: 20037747 | B12: MOBILECARE - GLORIETTA 5 | C12: G700065245 | D12: CIN | E12: SPCM | F12: 46063 | G12: ZA661-41635 | H12: SVC,APPLE PENCIL PRO-ITS | I12: G1CMQ944TG | J12: FNV7QW2V3R
A13: 20033067 | B13: MOBILECARE - GLORIETTA 5 | C13: G698996943 | D13: CIN | E13: GX02 | F13: 46045 | G13: 661-40219 | H13: Display, Starlight | I13: GMG545302701J88A0 | J13: F0Y436400CB1J88AQ
A14: 20033771 | B14: MOBILECARE - GLORIETTA 5 | C14: G698172583 | D14: CIN | E14: SPCM | F14: 46033 | G14: 661-18428 | H14: Battery, iPhone 12 Pro Max | I14: F8Y5437C5CKQ4C2BR | J14: F5D12721167Q4C0AW
A15: 20032779 | B15: MOBILECARE - GLORIETTA 5 | C15: G698169993 | D15: CIN | E15: SPCM | F15: 46038 | G15: 661-21991 | H15: Battery, iPhone 13 | I15: F8Y5426C80S18FKBS | J15: FG921742Z6318FMA1
A16: 20032477 | B16: MOBILECARE - GLORIETTA 5 | C16: G698141519 | D16: CIN | E16: SPCM | F16: 46049 | G16: 661-36918 | H16: Battery, iPhone 15 Pro Max | I16: FG9HNL005ZF00006TT | J16: F5DH0C01RVZ00006TU
... A46: 20030155 | B46: MOBILECARE - GLORIETTA 5 | C46: G696955305 | D46: CIN | E46: SPCM | F46: 46039 | G46: PP661-22981 | H46: Starlight, 128 GB, iPhone 13, ROW, CI/AR, Philippines | I46: HXKC77VGCL | J46: Q2MTFYDT90
A47: 20031096 | B47: MOBILECARE - GLORIETTA 5 | C47: G696952999 | D47: CIN | E47: SPCM | F47: 46038 | G47: PP661-22980 | H47: Midnight, 128 GB, iPhone 13, ROW, CI/AR, Philippines | I47: M9VH9K74WQ
A48: 20030917 | B48: MOBILECARE - GLORIETTA 5 | C48: G696952489 | D48: CIN | E48: SPCM | F48: 46035 | G48: 661-21991 | H48: Battery, iPhone 13 | I48: F8Y5451C06818FKBW | J48: F8Y24211P8E18FLAE
A49: 20030825 | B49: MOBILECARE - GLORIETTA 5 | C49: G696930065 | D49: CIN | E49: SPCM | F49: 46025 | G49: 661-42726 | H49: Display, iPhone 16 Pro | I49: G9PHKKT1ATJ00005DP | J49: GVCHB70036700005DQ
A50: 20030411 | B50: MOBILECARE - GLORIETTA 5 | C50: G681102838 | D50: CIN | E50: SPCM | F50: 46030 | G50: 661-36906 | H50: Camera , iPhone 15 Pro Max | I50: DN85296AJTR1W23B8 | J50: THA335602DK21PT64
A51: 20030411 | B51: MOBILECARE - GLORIETTA 5 | C51: G681102838 | D51: CIN | E51: SPCM | F51: 46030 | G51: 661-36916 | H51: TrueDepth Camera, iPhone 15 Pro Max | I51: FK1HJ7000CA00001WF | J51: DTTGYD02DEH00000YP
A52: 20030471 | B52: MOBILECARE - GLORIETTA 5 | C52: G696815897 | D52: CIN | E52: SPCM | F52: 46028 | G52: 661-30397 | H52: Battery, iPhone 14 Pro Max | I52: F8Y5453C4EW20J9BJ | J52: F8Y25361PX420JC28
A53: 20030803 | B53: MOBILECARE - GLORIETTA 5 | C53: G696815649 | D53: CIN | E53: SPCM | F53: 46045 | G53: ZP661-50227 | H53: iPad (A16) Wi-Fi, 128GB, Blue, CI/AR, CN | I53: C73Q0FRXDW | J53: GGXT3QL9R4
A54: 20030210 | B54: MOBILECARE - GLORIETTA 5 | C54: G696804775 | D54: CIN | E54: SPCM | F54: 46036 | G54: 661-14691 | H54: AirTag, 1PK | I54: HGHPT1BVP0GV | J54: HGGP7UN9P0GV
A55: 20030624 | B55: MOBILECARE - GLORIETTA 5 | C55: G696801495 | D55: CIN | E55: SPCM | F55: 46027 | G55: 661-30382 | H55: Battery, iPhone 14 Pro | I55: F8Y5465C9G7217WB2 | J55: F5D2427EGKA21PK7Z
A56: 20030271 | B56: MOBILECARE - GLORIETTA 5 | C56: G696711929 | D56: CIN | E56: SCOM | F56: 46031 | G56: 923-01365 | H56: EarPods with Lightning Connector | I56: FGJ54171391M854A8
A57: 20030493 | B57: MOBILECARE - GLORIETTA 5 | C57: G696621347 | D57: CIN | E57: SPCM | F57: 46032 | G57: 661-22309 | H57: Display, iPhone 13 Pro Max | I57: G9P5386M0QGPQCLAY | J57: G9P2105MF93PQCLA9
A58: 20030360 | B58: MOBILECARE - GLORIETTA 5 | C58: G696594131 | D58: CIN | E58: SPCM | F58: 46029 | G58: 661-16806 | H58: Display Assembly, Space Gray | I58: GMG544501R6NR8DB0 | J58: FP143930038249YAS
A59: 20028801 | B59: MOBILECARE - GLORIETTA 5 | C59: G696588687 | D59: CIN | E59: SPCM | F59: 46038 | G59: ZP661-22034 | H59: Space Gray, 64 GB, iPad 9th Generation, Wi-Fi, ITP | I59: LNP70FW6QN | J59: WHLQNVFNMP
A60: 20030255 | B60: MOBILECARE - GLORIETTA 5 | C60: G680716180 | D60: CIN | E60: SPCM | F60: 46027 | G60: 661-42726 | H60: Display, iPhone 16 Pro | I60: G9PHKKG2VF100005DP | J60: GVCHH100XKU00005DQ
A61: 20030095 | B61: MOBILECARE - GLORIETTA 5 | C61: G696305213 | D61: CIN | E61: SPCM | F61: 46029 | G61: 661-30397 | H61: Battery, iPhone 14 Pro Max | I61: F8Y5443C4VP20J9BH | J61: F5D25247DYP20J89U
A62: 20029913 | B62: MOBILECARE - GLORIETTA 5 | C62: G696284135 | D62: CIN | E62: SPCM | F62: 46025 | G62: 661-42727 | H62: TrueDepth Camera, iPhone 16 Pro | I62: J9KHFS00VJC0000FD3 | J62: FNJHADK0ESQ0000882
A63: 20029913 | B63: MOBILECARE - GLORIETTA 5 | C63: G696284135 | D63: CIN | E63: SPCM | F63: 46025 | G63: 661-42728 | H63: Camera, iPhone 16 Pro | I63: F0WHHG00KNA0000488 | J63: DN8HAG02N0100005KQ
A64: 20029345 | B64: MOBILECARE - GLORIETTA 5 | C64: G695977039 | D64: CIN | E64: SCOM | F64: 46024 | G64: 661-25799 | H64: Display, Starlight | I64: GMG533700QX1J88AR
A65: 20028979 | B65: MOBILECARE - GLORIETTA 5 | C65: G695885433 | D65: CIN | E65: SPCM | F65: 46039 | G65: ZP661-25136 | H65: Starlight, 64 GB, iPad Air 5th generation, Wi-Fi, ITP | I65: H0KKW31XH2 | J65: JF3G7NLXD0
A66: 20028275 | B66: MOBILECARE - GLORIETTA 5 | C66: G695556817 | D66: CIN | E66: SPCM | F66: 46036 | G66: ZP661-50228 | H66: iPad (A16) Wi-Fi, 128GB, Yellow, CI/AR, CN | I66: JN7QPNHR7H
A67: 20027368 | B67: MOBILECARE - GLORIETTA 5 | C67: G695548917 | D67: CIN | E67: SPCM | F67: 46036 | G67: PP661-22986 | H67: Starlight, 256 GB, iPhone 13, ROW, CI/AR, Philippines | I67: HT2CQQTCF6 | J67: V7G7WLHF6T
A68: 20027178 | B68: MOBILECARE - GLORIETTA 5 | C68: G695530425 | D68: CIN | E68: SPCM | F68: 46037 | G68: 661-25623 | H68: Logic Board, M2, 8-Core CPU, 8-core GPU, 8 GB, 256 GB | I68: C02312403KM0W98AU | J68: C02319203GL0W9CAF
A69: 20025335 | B69: MOBILECARE - GLORIETTA 5 | C69: G695524981 | D69: CIN | E69: SPCM | F69: 46036 | G69: ZP661-28887 | H69: Yellow, iPad 10th generation, 64GB, Wi-Fi, ITP | I69: LQ93F9QG09
...

Sheet iPhones
A1: iPhones Parts Usage Report
A2: Month | B2: Repair Closed Date | C2: Site Name | D2: Part Number | E2: Part Description
A3: =TEXT(B3:B6356,"MMMM") -> April | B3: =IFERROR(__xludf.DUMMYFUNCTION("IFERROR(CHOOSECOLS(FILTER(Masterlist!A3:J6356, ISNUMBER(SEARCH(""IPHONE"", Masterlist!H3:H6356))), 6, 2, 7, 8), ""No iPhones Found"")"),46123.0) -> 46123 | C3: =IFERROR(__xludf.DUMMYFUNCTION("""COMPUTED_VALUE"""),"MOBILECARE - GLORIETTA 5") -> MOBILECARE - GLORIETTA 5 | D3: =IFERROR(__xludf.DUMMYFUNCTION("""COMPUTED_VALUE"""),"661-36918") -> 661-36918 | E3: =IFERROR(__xludf.DUMMYFUNCTION("""COMPUTED_VALUE"""),"Battery, iPhone 15 Pro Max") -> Battery, iPhone 15 Pro Max
A4: =TEXT(B4:B6357,"MMMM") -> April | B4: =IFERROR(__xludf.DUMMYFUNCTION("""COMPUTED_VALUE"""),46117.0) -> 46117 | C4: =IFERROR(__xludf.DUMMYFUNCTION("""COMPUTED_VALUE"""),"MOBILECARE - GLORIETTA 5") -> MOBILECARE - GLORIETTA 5 | D4: =IFERROR(__xludf.DUMMYFUNCTION("""COMPUTED_VALUE"""),"661-56050") -> 661-56050 | E4: =IFERROR(__xludf.DUMMYFUNCTION("""COMPUTED_VALUE"""),"Display, iPhone 17 Pro Max") -> Display, iPhone 17 Pro Max
A5: =TEXT(B5:B6358,"MMMM") -> February | B5: =IFERROR(__xludf.DUMMYFUNCTION("""COMPUTED_VALUE"""),46058.0) -> 46058 | C5: =IFERROR(__xludf.DUMMYFUNCTION("""COMPUTED_VALUE"""),"MOBILECARE - GLORIETTA 5") -> MOBILECARE - GLORIETTA 5 | D5: =IFERROR(__xludf.DUMMYFUNCTION("""COMPUTED_VALUE"""),"661-21991") -> 661-21991 | E5: =IFERROR(__xludf.DUMMYFUNCTION("""COMPUTED_VALUE"""),"Battery, iPhone 13") -> Battery, iPhone 13
A6: =TEXT(B6:B6359,"MMMM") -> January | B6: =IFERROR(__xludf.DUMMYFUNCTION("""COMPUTED_VALUE"""),46033.0) -> 46033 | C6: =IFERROR(__xludf.DUMMYFUNCTION("""COMPUTED_VALUE"""),"MOBILECARE - GLORIETTA 5") -> MOBILECARE - GLORIETTA 5 | D6: =IFERROR(__xludf.DUMMYFUNCTION("""COMPUTED_VALUE"""),"661-18428") -> 661-18428 | E6: =IFERROR(__xludf.DUMMYFUNCTION("""COMPUTED_VALUE"""),"Battery, iPhone 12 Pro Max") -> Battery, iPhone 12 Pro Max
A7: =TEXT(B7:B6360,"MMMM") -> January | B7: =IFERROR(__xludf.DUMMYFUNCTION("""COMPUTED_VALUE"""),46038.0) -> 46038 | C7: =IFERROR(__xludf.DUMMYFUNCTION("""COMPUTED_VALUE"""),"MOBILECARE - GLORIETTA 5") -> MOBILECARE - GLORIETTA 5 | D7: =IFERROR(__xludf.DUMMYFUNCTION("""COMPUTED_VALUE"""),"661-21991") -> 661-21991 | E7: =IFERROR(__xludf.DUMMYFUNCTION("""COMPUTED_VALUE"""),"Battery, iPhone 13") -> Battery, iPhone 13
A8: =TEXT(B8:B6361,"MMMM") -> January | B8: =IFERROR(__xludf.DUMMYFUNCTION("""COMPUTED_VALUE"""),46049.0) -> 46049 | C8: =IFERROR(__xludf.DUMMYFUNCTION("""COMPUTED_VALUE"""),"MOBILECARE - GLORIETTA 5") -> MOBILECARE - GLORIETTA 5 | D8: =IFERROR(__xludf.DUMMYFUNCTION("""COMPUTED_VALUE"""),"661-36918") -> 661-36918 | E8: =IFERROR(__xludf.DUMMYFUNCTION("""COMPUTED_VALUE"""),"Battery, iPhone 15 Pro Max") -> Battery, iPhone 15 Pro Max
A9: =TEXT(B9:B6362,"MMMM") -> January | B9: =IFERROR(__xludf.DUMMYFUNCTION("""COMPUTED_VALUE"""),46049.0) -> 46049 | C9: =IFERROR(__xludf.DUMMYFUNCTION("""COMPUTED_VALUE"""),"MOBILECARE - GLORIETTA 5") -> MOBILECARE - GLORIETTA 5 | D9: =IFERROR(__xludf.DUMMYFUNCTION("""COMPUTED_VALUE"""),"PP661-22985") -> PP661-22985 | E9: =IFERROR(__xludf.DUMMYFUNCTION("""COMPUTED_VALUE"""),"Midnight, 256 GB, iPhone 13, ROW, CI/AR, Philippines") -> Midnight, 256 GB, iPhone 13, ROW, CI/AR, Philippines
A10: =TEXT(B10:B6363,"MMMM") -> January | B10: =IFERROR(__xludf.DUMMYFUNCTION("""COMPUTED_VALUE"""),46036.0) -> 46036 | C10: =IFERROR(__xludf.DUMMYFUNCTION("""COMPUTED_VALUE"""),"MOBILECARE - GLORIETTA 5") -> MOBILECARE - GLORIETTA 5 | D10: =IFERROR(__xludf.DUMMYFUNCTION("""COMPUTED_VALUE"""),"661-22309") -> 661-22309 | E10: =IFERROR(__xludf.DUMMYFUNCTION("""COMPUTED_VALUE"""),"Display, iPhone 13 Pro Max") -> Display, iPhone 13 Pro Max
A11: =TEXT(B11:B6364,"MMMM") -> January | B11: =IFERROR(__xludf.DUMMYFUNCTION("""COMPUTED_VALUE"""),46038.0) -> 46038 | C11: =IFERROR(__xludf.DUMMYFUNCTION("""COMPUTED_VALUE"""),"MOBILECARE - GLORIETTA 5") -> MOBILECARE - GLORIETTA 5 | D11: =IFERROR(__xludf.DUMMYFUNCTION("""COMPUTED_VALUE"""),"661-21991") -> 661-21991 | E11: =IFERROR(__xludf.DUMMYFUNCTION("""COMPUTED_VALUE"""),"Battery, iPhone 13") -> Battery, iPhone 13
A12: =TEXT(B12:B6365,"MMMM") -> January | B12: =IFERROR(__xludf.DUMMYFUNCTION("""COMPUTED_VALUE"""),46041.0) -> 46041 | C12: =IFERROR(__xludf.DUMMYFUNCTION("""COMPUTED_VALUE"""),"MOBILECARE - GLORIETTA 5") -> MOBILECARE - GLORIETTA 5 | D12: =IFERROR(__xludf.DUMMYFUNCTION("""COMPUTED_VALUE"""),"661-36913") -> 661-36913 | E12: =IFERROR(__xludf.DUMMYFUNCTION("""COMPUTED_VALUE"""),"Natural Titanium, Millimeter Wave, Back Glass, iPhone 15 Pro Max") -> Natural Titanium, Millimeter Wave, Back Glass, iPhone 15 Pro Max
A13: =TEXT(B13:B6366,"MMMM") -> January | B13: =IFERROR(__xludf.DUMMYFUNCTION("""COMPUTED_VALUE"""),46031.0) -> 46031 | C13: =IFERROR(__xludf.DUMMYFUNCTION("""COMPUTED_VALUE"""),"MOBILECARE - GLORIETTA 5") -> MOBILECARE - GLORIETTA 5 | D13: =IFERROR(__xludf.DUMMYFUNCTION("""COMPUTED_VALUE"""),"661-17920") -> 661-17920 | E13: =IFERROR(__xludf.DUMMYFUNCTION("""COMPUTED_VALUE"""),"Battery, iPhone 12 and 12 Pro") -> Battery, iPhone 12 and 12 Pro
A14: =TEXT(B14:B6367,"MMMM") -> January | B14: =IFERROR(__xludf.DUMMYFUNCTION("""COMPUTED_VALUE"""),46048.0) -> 46048 | C14: =IFERROR(__xludf.DUMMYFUNCTION("""COMPUTED_VALUE"""),"MOBILECARE - GLORIETTA 5") -> MOBILECARE - GLORIETTA 5 | D14: =IFERROR(__xludf.DUMMYFUNCTION("""COMPUTED_VALUE"""),"PP661-22980") -> PP661-22980 | E14: =IFERROR(__xludf.DUMMYFUNCTION("""COMPUTED_VALUE"""),"Midnight, 128 GB, iPhone 13, ROW, CI/AR, Philippines") -> Midnight, 128 GB, iPhone 13, ROW, CI/AR, Philippines
A15: =TEXT(B15:B6368,"MMMM") -> January | B15: =IFERROR(__xludf.DUMMYFUNCTION("""COMPUTED_VALUE"""),46035.0) -> 46035 | C15: =IFERROR(__xludf.DUMMYFUNCTION("""COMPUTED_VALUE"""),"MOBILECARE - GLORIETTA 5") -> MOBILECARE - GLORIETTA 5 | D15: =IFERROR(__xludf.DUMMYFUNCTION("""COMPUTED_VALUE"""),"661-22309") -> 661-22309 | E15: =IFERROR(__xludf.DUMMYFUNCTION("""COMPUTED_VALUE"""),"Display, iPhone 13 Pro Max") -> Display, iPhone 13 Pro Max
A16: =TEXT(B16:B6369,"MMMM") -> January | B16: =IFERROR(__xludf.DUMMYFUNCTION("""COMPUTED_VALUE"""),46043.0) -> 46043 | C16: =IFERROR(__xludf.DUMMYFUNCTION("""COMPUTED_VALUE"""),"MOBILECARE - GLORIETTA 5") -> MOBILECARE - GLORIETTA 5 | D16: =IFERROR(__xludf.DUMMYFUNCTION("""COMPUTED_VALUE"""),"PP661-22981") -> PP661-22981 | E16: =IFERROR(__xludf.DUMMYFUNCTION("""COMPUTED_VALUE"""),"Starlight, 128 GB, iPhone 13, ROW, CI/AR, Philippines") -> Starlight, 128 GB, iPhone 13, ROW, CI/AR, Philippines
A17: =TEXT(B17:B6370,"MMMM") -> January | B17: =IFERROR(__xludf.DUMMYFUNCTION("""COMPUTED_VALUE"""),46028.0) -> 46028 | C17: =IFERROR(__xludf.DUMMYFUNCTION("""COMPUTED_VALUE"""),"MOBILECARE - GLORIETTA 5") -> MOBILECARE - GLORIETTA 5 | D17: =IFERROR(__xludf.DUMMYFUNCTION("""COMPUTED_VALUE"""),"661-21991") -> 661-21991 | E17: =IFERROR(__xludf.DUMMYFUNCTION("""COMPUTED_VALUE"""),"Battery, iPhone 13") -> Battery, iPhone 13
A18: =TEXT(B18:B6371,"MMMM") -> January | B18: =IFERROR(__xludf.DUMMYFUNCTION("""COMPUTED_VALUE"""),46035.0) -> 46035 | C18: =IFERROR(__xludf.DUMMYFUNCTION("""COMPUTED_VALUE"""),"MOBILECARE - GLORIETTA 5") -> MOBILECARE - GLORIETTA 5 | D18: =IFERROR(__xludf.DUMMYFUNCTION("""COMPUTED_VALUE"""),"661-30373") -> 661-30373 | E18: =IFERROR(__xludf.DUMMYFUNCTION("""COMPUTED_VALUE"""),"Battery, iPhone 14") -> Battery, iPhone 14
A19: =TEXT(B19:B6372,"MMMM") -> January | B19: =IFERROR(__xludf.DUMMYFUNCTION("""COMPUTED_VALUE"""),46042.0) -> 46042 | C19: =IFERROR(__xludf.DUMMYFUNCTION("""COMPUTED_VALUE"""),"MOBILECARE - GLORIETTA 5") -> MOBILECARE - GLORIETTA 5 | D19: =IFERROR(__xludf.DUMMYFUNCTION("""COMPUTED_VALUE"""),"PP661-22986") -> PP661-22986 | E19: =IFERROR(__xludf.DUMMYFUNCTION("""COMPUTED_VALUE"""),"Starlight, 256 GB, iPhone 13, ROW, CI/AR, Philippines") -> Starlight, 256 GB, iPhone 13, ROW, CI/AR, Philippines
A20: =TEXT(B20:B6373,"MMMM") -> January | B20: =IFERROR(__xludf.DUMMYFUNCTION("""COMPUTED_VALUE"""),46031.0) -> 46031 | C20: =IFERROR(__xludf.DUMMYFUNCTION("""COMPUTED_VALUE"""),"MOBILECARE - GLORIETTA 5") -> MOBILECARE - GLORIETTA 5 | D20: =IFERROR(__xludf.DUMMYFUNCTION("""COMPUTED_VALUE"""),"661-22309") -> 661-22309 | E20: =IFERROR(__xludf.DUMMYFUNCTION("""COMPUTED_VALUE"""),"Display, iPhone 13 Pro Max") -> Display, iPhone 13 Pro Max
A21: =TEXT(B21:B6374,"MMMM") -> January | B21: =IFERROR(__xludf.DUMMYFUNCTION("""COMPUTED_VALUE"""),46030.0) -> 46030 | C21: =IFERROR(__xludf.DUMMYFUNCTION("""COMPUTED_VALUE"""),"MOBILECARE - GLORIETTA 5") -> MOBILECARE - GLORIETTA 5 | D21: =IFERROR(__xludf.DUMMYFUNCTION("""COMPUTED_VALUE"""),"661-22309") -> 661-22309 | E21: =IFERROR(__xludf.DUMMYFUNCTION("""COMPUTED_VALUE"""),"Display, iPhone 13 Pro Max") -> Display, iPhone 13 Pro Max
A22: =TEXT(B22:B6375,"MMMM") -> January | B22: =IFERROR(__xludf.DUMMYFUNCTION("""COMPUTED_VALUE"""),46026.0) -> 46026 | C22: =IFERROR(__xludf.DUMMYFUNCTION("""COMPUTED_VALUE"""),"MOBILECARE - GLORIETTA 5") -> MOBILECARE - GLORIETTA 5 | D22: =IFERROR(__xludf.DUMMYFUNCTION("""COMPUTED_VALUE"""),"661-21991") -> 661-21991 | E22: =IFERROR(__xludf.DUMMYFUNCTION("""COMPUTED_VALUE"""),"Battery, iPhone 13") -> Battery, iPhone 13
A23: =TEXT(B23:B6376,"MMMM") -> January | B23: =IFERROR(__xludf.DUMMYFUNCTION("""COMPUTED_VALUE"""),46028.0) -> 46028 | C23: =IFERROR(__xludf.DUMMYFUNCTION("""COMPUTED_VALUE"""),"MOBILECARE - GLORIETTA 5") -> MOBILECARE - GLORIETTA 5 | D23: =IFERROR(__xludf.DUMMYFUNCTION("""COMPUTED_VALUE"""),"661-13574") -> 661-13574 | E23: =IFERROR(__xludf.DUMMYFUNCTION("""COMPUTED_VALUE"""),"Battery, iPhone 11") -> Battery, iPhone 11
A24: =TEXT(B24:B6377,"MMMM") -> January | B24: =IFERROR(__xludf.DUMMYFUNCTION("""COMPUTED_VALUE"""),46030.0) -> 46030 | C24: =IFERROR(__xludf.DUMMYFUNCTION("""COMPUTED_VALUE"""),"MOBILECARE - GLORIETTA 5") -> MOBILECARE - GLORIETTA 5 | D24: =IFERROR(__xludf.DUMMYFUNCTION("""COMPUTED_VALUE"""),"661-17920") -> 661-17920 | E24: =IFERROR(__xludf.DUMMYFUNCTION("""COMPUTED_VALUE"""),"Battery, iPhone 12 and 12 Pro") -> Battery, iPhone 12 and 12 Pro
A25: =TEXT(B25:B6378,"MMMM") -> January | B25: =IFERROR(__xludf.DUMMYFUNCTION("""COMPUTED_VALUE"""),46039.0) -> 46039 | C25: =IFERROR(__xludf.DUMMYFUNCTION("""COMPUTED_VALUE"""),"MOBILECARE - GLORIETTA 5") -> MOBILECARE - GLORIETTA 5 | D25: =IFERROR(__xludf.DUMMYFUNCTION("""COMPUTED_VALUE"""),"PP661-22981") -> PP661-22981 | E25: =IFERROR(__xludf.DUMMYFUNCTION("""COMPUTED_VALUE"""),"Starlight, 128 GB, iPhone 13, ROW, CI/AR, Philippines") -> Starlight, 128 GB, iPhone 13, ROW, CI/AR, Philippines
A26: =TEXT(B26:B6379,"MMMM") -> January | B26: =IFERROR(__xludf.DUMMYFUNCTION("""COMPUTED_VALUE"""),46038.0) -> 46038 | C26: =IFERROR(__xludf.DUMMYFUNCTION("""COMPUTED_VALUE"""),"MOBILECARE - GLORIETTA 5") -> MOBILECARE - GLORIETTA 5 | D26: =IFERROR(__xludf.DUMMYFUNCTION("""COMPUTED_VALUE"""),"PP661-22980") -> PP661-22980 | E26: =IFERROR(__xludf.DUMMYFUNCTION("""COMPUTED_VALUE"""),"Midnight, 128 GB, iPhone 13, ROW, CI/AR, Philippines") -> Midnight, 128 GB, iPhone 13, ROW, CI/AR, Philippines
A27: =TEXT(B27:B6380,"MMMM") -> January | B27: =IFERROR(__xludf.DUMMYFUNCTION("""COMPUTED_VALUE"""),46035.0) -> 46035 | C27: =IFERROR(__xludf.DUMMYFUNCTION("""COMPUTED_VALUE"""),"MOBILECARE - GLORIETTA 5") -> MOBILECARE - GLORIETTA 5 | D27: =IFERROR(__xludf.DUMMYFUNCTION("""COMPUTED_VALUE"""),"661-21991") -> 661-21991 | E27: =IFERROR(__xludf.DUMMYFUNCTION("""COMPUTED_VALUE"""),"Battery, iPhone 13") -> Battery, iPhone 13
A28: =TEXT(B28:B6381,"MMMM") -> January | B28: =IFERROR(__xludf.DUMMYFUNCTION("""COMPUTED_VALUE"""),46025.0) -> 46025 | C28: =IFERROR(__xludf.DUMMYFUNCTION("""COMPUTED_VALUE"""),"MOBILECARE - GLORIETTA 5") -> MOBILECARE - GLORIETTA 5 | D28: =IFERROR(__xludf.DUMMYFUNCTION("""COMPUTED_VALUE"""),"661-42726") -> 661-42726 | E28: =IFERROR(__xludf.DUMMYFUNCTION("""COMPUTED_VALUE"""),"Display, iPhone 16 Pro") -> Display, iPhone 16 Pro
A29: =TEXT(B29:B6382,"MMMM") -> January | B29: =IFERROR(__xludf.DUMMYFUNCTION("""COMPUTED_VALUE"""),46030.0) -> 46030 | C29: =IFERROR(__xludf.DUMMYFUNCTION("""COMPUTED_VALUE"""),"MOBILECARE - GLORIETTA 5") -> MOBILECARE - GLORIETTA 5 | D29: =IFERROR(__xludf.DUMMYFUNCTION("""COMPUTED_VALUE"""),"661-36906") -> 661-36906 | E29: =IFERROR(__xludf.DUMMYFUNCTION("""COMPUTED_VALUE"""),"Camera , iPhone 15 Pro Max") -> Camera , iPhone 15 Pro Max
A30: =TEXT(B30:B6383,"MMMM") -> January | B30: =IFERROR(__xludf.DUMMYFUNCTION("""COMPUTED_VALUE"""),46030.0) -> 46030 | C30: =IFERROR(__xludf.DUMMYFUNCTION("""COMPUTED_VALUE"""),"MOBILECARE - GLORIETTA 5") -> MOBILECARE - GLORIETTA 5 | D30: =IFERROR(__xludf.DUMMYFUNCTION("""COMPUTED_VALUE"""),"661-36916") -> 661-36916 | E30: =IFERROR(__xludf.DUMMYFUNCTION("""COMPUTED_VALUE"""),"TrueDepth Camera, iPhone 15 Pro Max") -> TrueDepth Camera, iPhone 15 Pro Max
A31: =TEXT(B31:B6384,"MMMM") -> January | B31: =IFERROR(__xludf.DUMMYFUNCTION("""COMPUTED_VALUE"""),46028.0) -> 46028 | C31: =IFERROR(__xludf.DUMMYFUNCTION("""COMPUTED_VALUE"""),"MOBILECARE - GLORIETTA 5") -> MOBILECARE - GLORIETTA 5 | D31: =IFERROR(__xludf.DUMMYFUNCTION("""COMPUTED_VALUE"""),"661-30397") -> 661-30397 | E31: =IFERROR(__xludf.DUMMYFUNCTION("""COMPUTED_VALUE"""),"Battery, iPhone 14 Pro Max") -> Battery, iPhone 14 Pro Max
A32: =TEXT(B32:B6385,"MMMM") -> January | B32: =IFERROR(__xludf.DUMMYFUNCTION("""COMPUTED_VALUE"""),46027.0) -> 46027 | C32: =IFERROR(__xludf.DUMMYFUNCTION("""COMPUTED_VALUE"""),"MOBILECARE - GLORIETTA 5") -> MOBILECARE - GLORIETTA 5 | D32: =IFERROR(__xludf.DUMMYFUNCTION("""COMPUTED_VALUE"""),"661-30382") -> 661-30382 | E32: =IFERROR(__xludf.DUMMYFUNCTION("""COMPUTED_VALUE"""),"Battery, iPhone 14 Pro") -> Battery, iPhone 14 Pro
A33: =TEXT(B33:B6386,"MMMM") -> January | B33: =IFERROR(__xludf.DUMMYFUNCTION("""COMPUTED_VALUE"""),46032.0) -> 46032 | C33: =IFERROR(__xludf.DUMMYFUNCTION("""COMPUTED_VALUE"""),"MOBILECARE - GLORIETTA 5") -> MOBILECARE - GLORIETTA 5 | D33: =IFERROR(__xludf.DUMMYFUNCTION("""COMPUTED_VALUE"""),"661-22309") -> 661-22309 | E33: =IFERROR(__xludf.DUMMYFUNCTION("""COMPUTED_VALUE"""),"Display, iPhone 13 Pro Max") -> Display, iPhone 13 Pro Max
A34: =TEXT(B34:B6387,"MMMM") -> January | B34: =IFERROR(__xludf.DUMMYFUNCTION("""COMPUTED_VALUE"""),46027.0) -> 46027 | C34: =IFERROR(__xludf.DUMMYFUNCTION("""COMPUTED_VALUE"""),"MOBILECARE - GLORIETTA 5") -> MOBILECARE - GLORIETTA 5 | D34: =IFERROR(__xludf.DUMMYFUNCTION("""COMPUTED_VALUE"""),"661-42726") -> 661-42726 | E34: =IFERROR(__xludf.DUMMYFUNCTION("""COMPUTED_VALUE"""),"Display, iPhone 16 Pro") -> Display, iPhone 16 Pro
A35: =TEXT(B35:B6388,"MMMM") -> January | B35: =IFERROR(__xludf.DUMMYFUNCTION("""COMPUTED_VALUE"""),46029.0) -> 46029 | C35: =IFERROR(__xludf.DUMMYFUNCTION("""COMPUTED_VALUE"""),"MOBILECARE - GLORIETTA 5") -> MOBILECARE - GLORIETTA 5 | D35: =IFERROR(__xludf.DUMMYFUNCTION("""COMPUTED_VALUE"""),"661-30397") -> 661-30397 | E35: =IFERROR(__xludf.DUMMYFUNCTION("""COMPUTED_VALUE"""),"Battery, iPhone 14 Pro Max") -> Battery, iPhone 14 Pro Max
A36: =TEXT(B36:B6389,"MMMM") -> January | B36: =IFERROR(__xludf.DUMMYFUNCTION("""COMPUTED_VALUE"""),46025.0) -> 46025 | C36: =IFERROR(__xludf.DUMMYFUNCTION("""COMPUTED_VALUE"""),"MOBILECARE - GLORIETTA 5") -> MOBILECARE - GLORIETTA 5 | D36: =IFERROR(__xludf.DUMMYFUNCTION("""COMPUTED_VALUE"""),"661-42727") -> 661-42727 | E36: =IFERROR(__xludf.DUMMYFUNCTION("""COMPUTED_VALUE"""),"TrueDepth Camera, iPhone 16 Pro") -> TrueDepth Camera, iPhone 16 Pro
A37: =TEXT(B37:B6390,"MMMM") -> January | B37: =IFERROR(__xludf.DUMMYFUNCTION("""COMPUTED_VALUE"""),46025.0) -> 46025 | C37: =IFERROR(__xludf.DUMMYFUNCTION("""COMPUTED_VALUE"""),"MOBILECARE - GLORIETTA 5") -> MOBILECARE - GLORIETTA 5 | D37: =IFERROR(__xludf.DUMMYFUNCTION("""COMPUTED_VALUE"""),"661-42728") -> 661-42728 | E37: =IFERROR(__xludf.DUMMYFUNCTION("""COMPUTED_VALUE"""),"Camera, iPhone 16 Pro") -> Camera, iPhone 16 Pro
A38: =TEXT(B38:B6391,"MMMM") -> January | B38: =IFERROR(__xludf.DUMMYFUNCTION("""COMPUTED_VALUE"""),46036.0) -> 46036 | C38: =IFERROR(__xludf.DUMMYFUNCTION("""COMPUTED_VALUE"""),"MOBILECARE - GLORIETTA 5") -> MOBILECARE - GLORIETTA 5 | D38: =IFERROR(__xludf.DUMMYFUNCTION("""COMPUTED_VALUE"""),"PP661-22986") -> PP661-22986 | E38: =IFERROR(__xludf.DUMMYFUNCTION("""COMPUTED_VALUE"""),"Starlight, 256 GB, iPhone 13, ROW, CI/AR, Philippines") -> Starlight, 256 GB, iPhone 13, ROW, CI/AR, Philippines
A39: =TEXT(B39:B6392,"MMMM") -> March | B39: =IFERROR(__xludf.DUMMYFUNCTION("""COMPUTED_VALUE"""),46098.0) -> 46098 | C39: =IFERROR(__xludf.DUMMYFUNCTION("""COMPUTED_VALUE"""),"MOBILECARE - GLORIETTA 5") -> MOBILECARE - GLORIETTA 5 | D39: =IFERROR(__xludf.DUMMYFUNCTION("""COMPUTED_VALUE"""),"923-10996") -> 923-10996 | E39: =IFERROR(__xludf.DUMMYFUNCTION("""COMPUTED_VALUE"""),"Top Speaker, iPhone 16 Plus, non MMwave") -> Top Speaker, iPhone 16 Plus, non MMwave
A40: =TEXT(B40:B6393,"MMMM") -> June | B40: =IFERROR(__xludf.DUMMYFUNCTION("""COMPUTED_VALUE"""),46187.0) -> 46187 | C40: =IFERROR(__xludf.DUMMYFUNCTION("""COMPUTED_VALUE"""),"MOBILECARE - DAVAO") -> MOBILECARE - DAVAO | D40: =IFERROR(__xludf.DUMMYFUNCTION("""COMPUTED_VALUE"""),"TA661-36896") -> TA661-36896 | E40: =IFERROR(__xludf.DUMMYFUNCTION("""COMPUTED_VALUE"""),"Natural, iPhone 15 Pro Max, 256GB, ROW, CI/AR, Taiwan") -> Natural, iPhone 15 Pro Max, 256GB, ROW, CI/AR, Taiwan
...

Sheet Systems&BackGlass
A1: iPhones Parts Usage Report | G1: Most Used Parts in All Sites | K1: Top Sites with Most Used Parts | P1: Sites with Most Used MID SYSTEM | U1: Sites with Most Used REAR SYSTEM | Z1: Sites with Most Used BACK GLASS
A2: Month | B2: Repair Closed Date | C2: Site Name | D2: Part Number | E2: Part Description | G2: Part Number | H2: Site Description | I2: Total Quantity | K2: Site Name | L2: Total Quantity | O2: All | P2: Site | Q2: Quantity | T2: All | U2: Site | V2: Quantity | Y2: All | Z2: Site | AA2: Quantity
A3: =TEXT(B3:B1000,"MMMM") -> January | B3: =IFERROR(__xludf.DUMMYFUNCTION("IFERROR(CHOOSECOLS(FILTER(Masterlist!A3:J1000, ISNUMBER(SEARCH(""IPHONE"", Masterlist!H3:H1000)), (ISNUMBER(SEARCH(""Rear System"", Masterlist!H3:H1000)) + ISNUMBER(SEARCH(""Mid System"", Masterlist!H3:H1000)) + ISNUMBER(SEARCH(""Back Glass"", Masterlist!"&"H3:H1000))) > 0), 6, 2, 7, 8), ""No iPhones Found"")"),46041.0) -> 46041 | C3: =IFERROR(__xludf.DUMMYFUNCTION("""COMPUTED_VALUE"""),"MOBILECARE - GLORIETTA 5") -> MOBILECARE - GLORIETTA 5 | D3: =IFERROR(__xludf.DUMMYFUNCTION("""COMPUTED_VALUE"""),"661-36913") -> 661-36913 | E3: =IFERROR(__xludf.DUMMYFUNCTION("""COMPUTED_VALUE"""),"Natural Titanium, Millimeter Wave, Back Glass, iPhone 15 Pro Max") -> Natural Titanium, Millimeter Wave, Back Glass, iPhone 15 Pro Max | G3: =IFERROR(__xludf.DUMMYFUNCTION("LET( pairs, FILTER(HSTACK(D3:D1000, E3:E1000), E3:E1000<>""""), unique_pairs, UNIQUE(pairs), counts, BYROW(unique_pairs, LAMBDA(r, COUNTIFS(D3:D1000, INDEX(r,1,1), E3:E1000, INDEX(r,1,2)))), SORT(HSTACK(unique_pairs, counts), 3, FALSE) )"),"PP661-23455") -> PP661-23455 | H3: =IFERROR(__xludf.DUMMYFUNCTION("""COMPUTED_VALUE"""),"iPhone 13, Starlight, 128GB, Logic Board Assy Rear System, ROW") -> iPhone 13, Starlight, 128GB, Logic Board Assy Rear System, ROW | I3: =IFERROR(__xludf.DUMMYFUNCTION("""COMPUTED_VALUE"""),212.0) -> 212 | K3: =IFERROR(__xludf.DUMMYFUNCTION("LET( sites, UNIQUE(FILTER(C3:C1000, C3:C1000<>"""")), counts, MAP(sites, LAMBDA(s, COUNTIF(C3:C1000, s))), SORT(HSTACK(sites, counts), 2, FALSE) )"),"MOBILECARE - NEWPOINT MALL") -> MOBILECARE - NEWPOINT MALL | L3: =IFERROR(__xludf.DUMMYFUNCTION("""COMPUTED_VALUE"""),130.0) -> 130 | P3: =IFERROR(__xludf.DUMMYFUNCTION("QUERY('Systems&BackGlass'!A3:E1000, ""SELECT C, COUNT(C) WHERE lower(E) CONTAINS 'mid system' "" & IF(O2=""All"", """", ""AND lower(A) = '"" & LOWER(TRIM(O2)) & ""' "") & ""GROUP BY C ORDER BY COUNT(C) DESC LABEL COUNT(C) ''"", 0)"),"MOBILECARE - NEWPOINT MALL") -> MOBILECARE - NEWPOINT MALL | Q3: =IFERROR(__xludf.DUMMYFUNCTION("""COMPUTED_VALUE"""),70.0) -> 70 | U3: =IFERROR(__xludf.DUMMYFUNCTION("QUERY('Systems&BackGlass'!A3:E1000, ""SELECT C, COUNT(C) WHERE lower(E) CONTAINS 'rear system' "" & IF(T2=""All"", """", ""AND lower(A) = '"" & LOWER(TRIM(T2)) & ""' "") & ""GROUP BY C ORDER BY COUNT(C) DESC LABEL COUNT(C) ''"", 0)"),"MOBILECARE - FESTIVE WALK ILOILO") -> MOBILECARE - FESTIVE WALK ILOILO | V3: =IFERROR(__xludf.DUMMYFUNCTION("""COMPUTED_VALUE"""),73.0) -> 73 | Z3: =IFERROR(__xludf.DUMMYFUNCTION("QUERY('Systems&BackGlass'!A3:E1000, ""SELECT C, COUNT(C) WHERE lower(E) CONTAINS 'back glass' "" & IF(Y2=""All"", """", ""AND lower(A) = '"" & LOWER(TRIM(Y2)) & ""' "") & ""GROUP BY C ORDER BY COUNT(C) DESC LABEL COUNT(C) ''"", 0)"),"MOBILECARE - LIMA ESTATE") -> MOBILECARE - LIMA ESTATE | AA3: =IFERROR(__xludf.DUMMYFUNCTION("""COMPUTED_VALUE"""),7.0) -> 7
A4: =TEXT(B4:B1001,"MMMM") -> May | B4: =IFERROR(__xludf.DUMMYFUNCTION("""COMPUTED_VALUE"""),46158.0) -> 46158 | C4: =IFERROR(__xludf.DUMMYFUNCTION("""COMPUTED_VALUE"""),"MOBILECARE - DAVAO") -> MOBILECARE - DAVAO | D4: =IFERROR(__xludf.DUMMYFUNCTION("""COMPUTED_VALUE"""),"TA661-36693") -> TA661-36693 | E4: =IFERROR(__xludf.DUMMYFUNCTION("""COMPUTED_VALUE"""),"iPhone 15, Yellow, 128GB, Logic Board Assy Mid System, ROW") -> iPhone 15, Yellow, 128GB, Logic Board Assy Mid System, ROW | G4: =IFERROR(__xludf.DUMMYFUNCTION("""COMPUTED_VALUE"""),"PP661-23454") -> PP661-23454 | H4: =IFERROR(__xludf.DUMMYFUNCTION("""COMPUTED_VALUE"""),"iPhone 13, Midnight, 128GB, Logic Board Assy Rear System, ROW") -> iPhone 13, Midnight, 128GB, Logic Board Assy Rear System, ROW | I4: =IFERROR(__xludf.DUMMYFUNCTION("""COMPUTED_VALUE"""),149.0) -> 149 | K4: =IFERROR(__xludf.DUMMYFUNCTION("""COMPUTED_VALUE"""),"MOBILECARE - DAVAO") -> MOBILECARE - DAVAO | L4: =IFERROR(__xludf.DUMMYFUNCTION("""COMPUTED_VALUE"""),122.0) -> 122 | P4: =IFERROR(__xludf.DUMMYFUNCTION("""COMPUTED_VALUE"""),"MOBILECARE - DAVAO") -> MOBILECARE - DAVAO | Q4: =IFERROR(__xludf.DUMMYFUNCTION("""COMPUTED_VALUE"""),51.0) -> 51 | U4: =IFERROR(__xludf.DUMMYFUNCTION("""COMPUTED_VALUE"""),"MOBILECARE - DAVAO") -> MOBILECARE - DAVAO | V4: =IFERROR(__xludf.DUMMYFUNCTION("""COMPUTED_VALUE"""),67.0) -> 67 | Z4: =IFERROR(__xludf.DUMMYFUNCTION("""COMPUTED_VALUE"""),"MOBILECARE - GLORIETTA 5") -> MOBILECARE - GLORIETTA 5 | AA4: =IFERROR(__xludf.DUMMYFUNCTION("""COMPUTED_VALUE"""),6.0) -> 6
A5: =TEXT(B5:B1002,"MMMM") -> January | B5: =IFERROR(__xludf.DUMMYFUNCTION("""COMPUTED_VALUE"""),46053.0) -> 46053 | C5: =IFERROR(__xludf.DUMMYFUNCTION("""COMPUTED_VALUE"""),"MOBILECARE - DAVAO") -> MOBILECARE - DAVAO | D5: =IFERROR(__xludf.DUMMYFUNCTION("""COMPUTED_VALUE"""),"TA661-43605") -> TA661-43605 | E5: =IFERROR(__xludf.DUMMYFUNCTION("""COMPUTED_VALUE"""),"128GB, Black, ROW, iPhone 16, Logic Board Assy Mid System") -> 128GB, Black, ROW, iPhone 16, Logic Board Assy Mid System | G5: =IFERROR(__xludf.DUMMYFUNCTION("""COMPUTED_VALUE"""),"PP661-28868") -> PP661-28868 | H5: =IFERROR(__xludf.DUMMYFUNCTION("""COMPUTED_VALUE"""),"iPhone 14, Midnight, 128GB, Logic Board Assy Mid System, ROW") -> iPhone 14, Midnight, 128GB, Logic Board Assy Mid System, ROW | I5: =IFERROR(__xludf.DUMMYFUNCTION("""COMPUTED_VALUE"""),39.0) -> 39 | K5: =IFERROR(__xludf.DUMMYFUNCTION("""COMPUTED_VALUE"""),"MOBILECARE - FESTIVE WALK ILOILO") -> MOBILECARE - FESTIVE WALK ILOILO | L5: =IFERROR(__xludf.DUMMYFUNCTION("""COMPUTED_VALUE"""),111.0) -> 111 | P5: =IFERROR(__xludf.DUMMYFUNCTION("""COMPUTED_VALUE"""),"MOBILECARE - LIMA ESTATE") -> MOBILECARE - LIMA ESTATE | Q5: =IFERROR(__xludf.DUMMYFUNCTION("""COMPUTED_VALUE"""),46.0) -> 46 | U5: =IFERROR(__xludf.DUMMYFUNCTION("""COMPUTED_VALUE"""),"MOBILECARE - NEWPOINT MALL") -> MOBILECARE - NEWPOINT MALL | V5: =IFERROR(__xludf.DUMMYFUNCTION("""COMPUTED_VALUE"""),55.0) -> 55 | Z5: =IFERROR(__xludf.DUMMYFUNCTION("""COMPUTED_VALUE"""),"MOBILECARE - NEWPOINT MALL") -> MOBILECARE - NEWPOINT MALL | AA5: =IFERROR(__xludf.DUMMYFUNCTION("""COMPUTED_VALUE"""),5.0) -> 5
A6: =TEXT(B6:B1003,"MMMM") -> February | B6: =IFERROR(__xludf.DUMMYFUNCTION("""COMPUTED_VALUE"""),46056.0) -> 46056 | C6: =IFERROR(__xludf.DUMMYFUNCTION("""COMPUTED_VALUE"""),"MOBILECARE - DAVAO") -> MOBILECARE - DAVAO | D6: =IFERROR(__xludf.DUMMYFUNCTION("""COMPUTED_VALUE"""),"PP661-23455") -> PP661-23455 | E6: =IFERROR(__xludf.DUMMYFUNCTION("""COMPUTED_VALUE"""),"iPhone 13, Starlight, 128GB, Logic Board Assy Rear System, ROW") -> iPhone 13, Starlight, 128GB, Logic Board Assy Rear System, ROW | G6: =IFERROR(__xludf.DUMMYFUNCTION("""COMPUTED_VALUE"""),"TA661-36694") -> TA661-36694 | H6: =IFERROR(__xludf.DUMMYFUNCTION("""COMPUTED_VALUE"""),"iPhone 15, Blue, 128GB, Logic Board Assy Mid System, ROW") -> iPhone 15, Blue, 128GB, Logic Board Assy Mid System, ROW | I6: =IFERROR(__xludf.DUMMYFUNCTION("""COMPUTED_VALUE"""),35.0) -> 35 | K6: =IFERROR(__xludf.DUMMYFUNCTION("""COMPUTED_VALUE"""),"MOBILECARE - LIMA ESTATE") -> MOBILECARE - LIMA ESTATE | L6: =IFERROR(__xludf.DUMMYFUNCTION("""COMPUTED_VALUE"""),107.0) -> 107 | P6: =IFERROR(__xludf.DUMMYFUNCTION("""COMPUTED_VALUE"""),"MOBILECARE - FESTIVE WALK ILOILO") -> MOBILECARE - FESTIVE WALK ILOILO | Q6: =IFERROR(__xludf.DUMMYFUNCTION("""COMPUTED_VALUE"""),37.0) -> 37 | U6: =IFERROR(__xludf.DUMMYFUNCTION("""COMPUTED_VALUE"""),"MOBILECARE - LIMA ESTATE") -> MOBILECARE - LIMA ESTATE | V6: =IFERROR(__xludf.DUMMYFUNCTION("""COMPUTED_VALUE"""),54.0) -> 54 | Z6: =IFERROR(__xludf.DUMMYFUNCTION("""COMPUTED_VALUE"""),"MOBILECARE - VERTIS NORTH") -> MOBILECARE - VERTIS NORTH | AA6: =IFERROR(__xludf.DUMMYFUNCTION("""COMPUTED_VALUE"""),5.0) -> 5
A7: =TEXT(B7:B1004,"MMMM") -> January | B7: =IFERROR(__xludf.DUMMYFUNCTION("""COMPUTED_VALUE"""),46043.0) -> 46043 | C7: =IFERROR(__xludf.DUMMYFUNCTION("""COMPUTED_VALUE"""),"MOBILECARE - DAVAO") -> MOBILECARE - DAVAO | D7: =IFERROR(__xludf.DUMMYFUNCTION("""COMPUTED_VALUE"""),"PP661-23455") -> PP661-23455 | E7: =IFERROR(__xludf.DUMMYFUNCTION("""COMPUTED_VALUE"""),"iPhone 13, Starlight, 128GB, Logic Board Assy Rear System, ROW") -> iPhone 13, Starlight, 128GB, Logic Board Assy Rear System, ROW | G7: =IFERROR(__xludf.DUMMYFUNCTION("""COMPUTED_VALUE"""),"PP661-28869") -> PP661-28869 | H7: =IFERROR(__xludf.DUMMYFUNCTION("""COMPUTED_VALUE"""),"iPhone 14, Starlight, 128GB, Logic Board Assy Mid System, ROW") -> iPhone 14, Starlight, 128GB, Logic Board Assy Mid System, ROW | I7: =IFERROR(__xludf.DUMMYFUNCTION("""COMPUTED_VALUE"""),27.0) -> 27 | K7: =IFERROR(__xludf.DUMMYFUNCTION("""COMPUTED_VALUE"""),"MOBILECARE - NAGA") -> MOBILECARE - NAGA | L7: =IFERROR(__xludf.DUMMYFUNCTION("""COMPUTED_VALUE"""),66.0) -> 66 | P7: =IFERROR(__xludf.DUMMYFUNCTION("""COMPUTED_VALUE"""),"MOBILECARE - NAGA") -> MOBILECARE - NAGA | Q7: =IFERROR(__xludf.DUMMYFUNCTION("""COMPUTED_VALUE"""),33.0) -> 33 | U7: =IFERROR(__xludf.DUMMYFUNCTION("""COMPUTED_VALUE"""),"MOBILECARE - NAGA") -> MOBILECARE - NAGA | V7: =IFERROR(__xludf.DUMMYFUNCTION("""COMPUTED_VALUE"""),32.0) -> 32 | Z7: =IFERROR(__xludf.DUMMYFUNCTION("""COMPUTED_VALUE"""),"MOBILECARE - APP FESTIVAL MALL") -> MOBILECARE - APP FESTIVAL MALL | AA7: =IFERROR(__xludf.DUMMYFUNCTION("""COMPUTED_VALUE"""),4.0) -> 4
A8: =TEXT(B8:B1005,"MMMM") -> January | B8: =IFERROR(__xludf.DUMMYFUNCTION("""COMPUTED_VALUE"""),46048.0) -> 46048 | C8: =IFERROR(__xludf.DUMMYFUNCTION("""COMPUTED_VALUE"""),"MOBILECARE - DAVAO") -> MOBILECARE - DAVAO | D8: =IFERROR(__xludf.DUMMYFUNCTION("""COMPUTED_VALUE"""),"TA661-43610") -> TA661-43610 | E8: =IFERROR(__xludf.DUMMYFUNCTION("""COMPUTED_VALUE"""),"256GB, Black, ROW, iPhone 16, Logic Board Assy Mid System") -> 256GB, Black, ROW, iPhone 16, Logic Board Assy Mid System | G8: =IFERROR(__xludf.DUMMYFUNCTION("""COMPUTED_VALUE"""),"TA661-36691") -> TA661-36691 | H8: =IFERROR(__xludf.DUMMYFUNCTION("""COMPUTED_VALUE"""),"iPhone 15, Black, 128GB, Logic Board Assy Mid System, ROW") -> iPhone 15, Black, 128GB, Logic Board Assy Mid System, ROW | I8: =IFERROR(__xludf.DUMMYFUNCTION("""COMPUTED_VALUE"""),23.0) -> 23 | K8: =IFERROR(__xludf.DUMMYFUNCTION("""COMPUTED_VALUE"""),"MOBILECARE - CEBU") -> MOBILECARE - CEBU | L8: =IFERROR(__xludf.DUMMYFUNCTION("""COMPUTED_VALUE"""),59.0) -> 59 | P8: =IFERROR(__xludf.DUMMYFUNCTION("""COMPUTED_VALUE"""),"MOBILECARE - CEBU") -> MOBILECARE - CEBU | Q8: =IFERROR(__xludf.DUMMYFUNCTION("""COMPUTED_VALUE"""),28.0) -> 28 | U8: =IFERROR(__xludf.DUMMYFUNCTION("""COMPUTED_VALUE"""),"MOBILECARE - CEBU") -> MOBILECARE - CEBU | V8: =IFERROR(__xludf.DUMMYFUNCTION("""COMPUTED_VALUE"""),29.0) -> 29 | Z8: =IFERROR(__xludf.DUMMYFUNCTION("""COMPUTED_VALUE"""),"MOBILECARE - APP MAGNOLIA") -> MOBILECARE - APP MAGNOLIA | AA8: =IFERROR(__xludf.DUMMYFUNCTION("""COMPUTED_VALUE"""),4.0) -> 4
A9: =TEXT(B9:B1006,"MMMM") -> January | B9: =IFERROR(__xludf.DUMMYFUNCTION("""COMPUTED_VALUE"""),46053.0) -> 46053 | C9: =IFERROR(__xludf.DUMMYFUNCTION("""COMPUTED_VALUE"""),"MOBILECARE - DAVAO") -> MOBILECARE - DAVAO | D9: =IFERROR(__xludf.DUMMYFUNCTION("""COMPUTED_VALUE"""),"PP661-23455") -> PP661-23455 | E9: =IFERROR(__xludf.DUMMYFUNCTION("""COMPUTED_VALUE"""),"iPhone 13, Starlight, 128GB, Logic Board Assy Rear System, ROW") -> iPhone 13, Starlight, 128GB, Logic Board Assy Rear System, ROW | G9: =IFERROR(__xludf.DUMMYFUNCTION("""COMPUTED_VALUE"""),"PP661-28871") -> PP661-28871 | H9: =IFERROR(__xludf.DUMMYFUNCTION("""COMPUTED_VALUE"""),"iPhone 14, Blue, 128GB, Logic Board Assy Mid System, ROW") -> iPhone 14, Blue, 128GB, Logic Board Assy Mid System, ROW | I9: =IFERROR(__xludf.DUMMYFUNCTION("""COMPUTED_VALUE"""),17.0) -> 17 | K9: =IFERROR(__xludf.DUMMYFUNCTION("""COMPUTED_VALUE"""),"MOBILECARE - LA UNION") -> MOBILECARE - LA UNION | L9: =IFERROR(__xludf.DUMMYFUNCTION("""COMPUTED_VALUE"""),47.0) -> 47 | P9: =IFERROR(__xludf.DUMMYFUNCTION("""COMPUTED_VALUE"""),"MOBILECARE - CAGAYAN DE ORO") -> MOBILECARE - CAGAYAN DE ORO | Q9: =IFERROR(__xludf.DUMMYFUNCTION("""COMPUTED_VALUE"""),27.0) -> 27 | U9: =IFERROR(__xludf.DUMMYFUNCTION("""COMPUTED_VALUE"""),"MOBILECARE - LA UNION") -> MOBILECARE - LA UNION | V9: =IFERROR(__xludf.DUMMYFUNCTION("""COMPUTED_VALUE"""),25.0) -> 25 | Z9: =IFERROR(__xludf.DUMMYFUNCTION("""COMPUTED_VALUE"""),"MOBILECARE - APP THE ANNEX") -> MOBILECARE - APP THE ANNEX | AA9: =IFERROR(__xludf.DUMMYFUNCTION("""COMPUTED_VALUE"""),4.0) -> 4
A10: =TEXT(B10:B1007,"MMMM") -> January | B10: =IFERROR(__xludf.DUMMYFUNCTION("""COMPUTED_VALUE"""),46048.0) -> 46048 | C10: =IFERROR(__xludf.DUMMYFUNCTION("""COMPUTED_VALUE"""),"MOBILECARE - DAVAO") -> MOBILECARE - DAVAO | D10: =IFERROR(__xludf.DUMMYFUNCTION("""COMPUTED_VALUE"""),"PP661-23454") -> PP661-23454 | E10: =IFERROR(__xludf.DUMMYFUNCTION("""COMPUTED_VALUE"""),"iPhone 13, Midnight, 128GB, Logic Board Assy Rear System, ROW") -> iPhone 13, Midnight, 128GB, Logic Board Assy Rear System, ROW | G10: =IFERROR(__xludf.DUMMYFUNCTION("""COMPUTED_VALUE"""),"TA661-36692") -> TA661-36692 | H10: =IFERROR(__xludf.DUMMYFUNCTION("""COMPUTED_VALUE"""),"iPhone 15, Pink, 128GB, Logic Board Assy Mid System, ROW") -> iPhone 15, Pink, 128GB, Logic Board Assy Mid System, ROW | I10: =IFERROR(__xludf.DUMMYFUNCTION("""COMPUTED_VALUE"""),12.0) -> 12 | K10: =IFERROR(__xludf.DUMMYFUNCTION("""COMPUTED_VALUE"""),"MOBILECARE - CAGAYAN DE ORO") -> MOBILECARE - CAGAYAN DE ORO | L10: =IFERROR(__xludf.DUMMYFUNCTION("""COMPUTED_VALUE"""),41.0) -> 41 | P10: =IFERROR(__xludf.DUMMYFUNCTION("""COMPUTED_VALUE"""),"MOBILECARE - LA UNION") -> MOBILECARE - LA UNION | Q10: =IFERROR(__xludf.DUMMYFUNCTION("""COMPUTED_VALUE"""),18.0) -> 18 | U10: =IFERROR(__xludf.DUMMYFUNCTION("""COMPUTED_VALUE"""),"MOBILECARE - ZAMBOANGA") -> MOBILECARE - ZAMBOANGA | V10: =IFERROR(__xludf.DUMMYFUNCTION("""COMPUTED_VALUE"""),17.0) -> 17 | Z10: =IFERROR(__xludf.DUMMYFUNCTION("""COMPUTED_VALUE"""),"MOBILECARE - APP TRINOMA") -> MOBILECARE - APP TRINOMA | AA10: =IFERROR(__xludf.DUMMYFUNCTION("""COMPUTED_VALUE"""),4.0) -> 4
A11: =TEXT(B11:B1008,"MMMM") -> January | B11: =IFERROR(__xludf.DUMMYFUNCTION("""COMPUTED_VALUE"""),46045.0) -> 46045 | C11: =IFERROR(__xludf.DUMMYFUNCTION("""COMPUTED_VALUE"""),"MOBILECARE - DAVAO") -> MOBILECARE - DAVAO | D11: =IFERROR(__xludf.DUMMYFUNCTION("""COMPUTED_VALUE"""),"PP661-23455") -> PP661-23455 | E11: =IFERROR(__xludf.DUMMYFUNCTION("""COMPUTED_VALUE"""),"iPhone 13, Starlight, 128GB, Logic Board Assy Rear System, ROW") -> iPhone 13, Starlight, 128GB, Logic Board Assy Rear System, ROW | G11: =IFERROR(__xludf.DUMMYFUNCTION("""COMPUTED_VALUE"""),"TA661-43606") -> TA661-43606 | H11: =IFERROR(__xludf.DUMMYFUNCTION("""COMPUTED_VALUE"""),"128GB, White, ROW, iPhone 16, Logic Board Assy Mid System") -> 128GB, White, ROW, iPhone 16, Logic Board Assy Mid System | I11: =IFERROR(__xludf.DUMMYFUNCTION("""COMPUTED_VALUE"""),12.0) -> 12 | K11: =IFERROR(__xludf.DUMMYFUNCTION("""COMPUTED_VALUE"""),"MOBILECARE - ZAMBOANGA") -> MOBILECARE - ZAMBOANGA | L11: =IFERROR(__xludf.DUMMYFUNCTION("""COMPUTED_VALUE"""),32.0) -> 32 | P11: =IFERROR(__xludf.DUMMYFUNCTION("""COMPUTED_VALUE"""),"MOBILECARE - ZAMBOANGA") -> MOBILECARE - ZAMBOANGA | Q11: =IFERROR(__xludf.DUMMYFUNCTION("""COMPUTED_VALUE"""),12.0) -> 12 | U11: =IFERROR(__xludf.DUMMYFUNCTION("""COMPUTED_VALUE"""),"MOBILECARE - CAGAYAN DE ORO") -> MOBILECARE - CAGAYAN DE ORO | V11: =IFERROR(__xludf.DUMMYFUNCTION("""COMPUTED_VALUE"""),12.0) -> 12 | Z11: =IFERROR(__xludf.DUMMYFUNCTION("""COMPUTED_VALUE"""),"MOBILECARE - DAVAO") -> MOBILECARE - DAVAO | AA11: =IFERROR(__xludf.DUMMYFUNCTION("""COMPUTED_VALUE"""),4.0) -> 4
A12: =TEXT(B12:B1009,"MMMM") -> January | B12: =IFERROR(__xludf.DUMMYFUNCTION("""COMPUTED_VALUE"""),46044.0) -> 46044 | C12: =IFERROR(__xludf.DUMMYFUNCTION("""COMPUTED_VALUE"""),"MOBILECARE - DAVAO") -> MOBILECARE - DAVAO | D12: =IFERROR(__xludf.DUMMYFUNCTION("""COMPUTED_VALUE"""),"PP661-23455") -> PP661-23455 | E12: =IFERROR(__xludf.DUMMYFUNCTION("""COMPUTED_VALUE"""),"iPhone 13, Starlight, 128GB, Logic Board Assy Rear System, ROW") -> iPhone 13, Starlight, 128GB, Logic Board Assy Rear System, ROW | G12: =IFERROR(__xludf.DUMMYFUNCTION("""COMPUTED_VALUE"""),"TA661-43605") -> TA661-43605 | H12: =IFERROR(__xludf.DUMMYFUNCTION("""COMPUTED_VALUE"""),"128GB, Black, ROW, iPhone 16, Logic Board Assy Mid System") -> 128GB, Black, ROW, iPhone 16, Logic Board Assy Mid System | I12: =IFERROR(__xludf.DUMMYFUNCTION("""COMPUTED_VALUE"""),11.0) -> 11 | K12: =IFERROR(__xludf.DUMMYFUNCTION("""COMPUTED_VALUE"""),"MOBILECARE - GLORIETTA 5") -> MOBILECARE - GLORIETTA 5 | L12: =IFERROR(__xludf.DUMMYFUNCTION("""COMPUTED_VALUE"""),6.0) -> 6 | P12: =IFERROR(__xludf.DUMMYFUNCTION("""COMPUTED_VALUE"""),"MOBILECARE - APP SM LANANG") -> MOBILECARE - APP SM LANANG | Q12: =IFERROR(__xludf.DUMMYFUNCTION("""COMPUTED_VALUE"""),1.0) -> 1 | U12: =IFERROR(__xludf.DUMMYFUNCTION("""COMPUTED_VALUE"""),"MOBILECARE - APP SM LANANG") -> MOBILECARE - APP SM LANANG | V12: =IFERROR(__xludf.DUMMYFUNCTION("""COMPUTED_VALUE"""),3.0) -> 3 | Z12: =IFERROR(__xludf.DUMMYFUNCTION("""COMPUTED_VALUE"""),"MOBILECARE - LA UNION") -> MOBILECARE - LA UNION | AA12: =IFERROR(__xludf.DUMMYFUNCTION("""COMPUTED_VALUE"""),4.0) -> 4
A13: =TEXT(B13:B1010,"MMMM") -> February | B13: =IFERROR(__xludf.DUMMYFUNCTION("""COMPUTED_VALUE"""),46054.0) -> 46054 | C13: =IFERROR(__xludf.DUMMYFUNCTION("""COMPUTED_VALUE"""),"MOBILECARE - DAVAO") -> MOBILECARE - DAVAO | D13: =IFERROR(__xludf.DUMMYFUNCTION("""COMPUTED_VALUE"""),"PP661-23455") -> PP661-23455 | E13: =IFERROR(__xludf.DUMMYFUNCTION("""COMPUTED_VALUE"""),"iPhone 13, Starlight, 128GB, Logic Board Assy Rear System, ROW") -> iPhone 13, Starlight, 128GB, Logic Board Assy Rear System, ROW | G13: =IFERROR(__xludf.DUMMYFUNCTION("""COMPUTED_VALUE"""),"661-44960") -> 661-44960 | H13: =IFERROR(__xludf.DUMMYFUNCTION("""COMPUTED_VALUE"""),"Desert Titanium, Back Glass, iPhone 16 Pro Max") -> Desert Titanium, Back Glass, iPhone 16 Pro Max | I13: =IFERROR(__xludf.DUMMYFUNCTION("""COMPUTED_VALUE"""),10.0) -> 10 | K13: =IFERROR(__xludf.DUMMYFUNCTION("""COMPUTED_VALUE"""),"MOBILECARE - VERTIS NORTH") -> MOBILECARE - VERTIS NORTH | L13: =IFERROR(__xludf.DUMMYFUNCTION("""COMPUTED_VALUE"""),5.0) -> 5 | U13: =IFERROR(__xludf.DUMMYFUNCTION("""COMPUTED_VALUE"""),"MOBILECARE - APP THE ANNEX") -> MOBILECARE - APP THE ANNEX | V13: =IFERROR(__xludf.DUMMYFUNCTION("""COMPUTED_VALUE"""),1.0) -> 1 | Z13: =IFERROR(__xludf.DUMMYFUNCTION("""COMPUTED_VALUE"""),"MOBILECARE - NORTHEAST SQUARE") -> MOBILECARE - NORTHEAST SQUARE | AA13: =IFERROR(__xludf.DUMMYFUNCTION("""COMPUTED_VALUE"""),3.0) -> 3
A14: =TEXT(B14:B1011,"MMMM") -> January | B14: =IFERROR(__xludf.DUMMYFUNCTION("""COMPUTED_VALUE"""),46050.0) -> 46050 | C14: =IFERROR(__xludf.DUMMYFUNCTION("""COMPUTED_VALUE"""),"MOBILECARE - DAVAO") -> MOBILECARE - DAVAO | D14: =IFERROR(__xludf.DUMMYFUNCTION("""COMPUTED_VALUE"""),"PP661-23455") -> PP661-23455 | E14: =IFERROR(__xludf.DUMMYFUNCTION("""COMPUTED_VALUE"""),"iPhone 13, Starlight, 128GB, Logic Board Assy Rear System, ROW") -> iPhone 13, Starlight, 128GB, Logic Board Assy Rear System, ROW | G14: =IFERROR(__xludf.DUMMYFUNCTION("""COMPUTED_VALUE"""),"TA661-36696") -> TA661-36696 | H14: =IFERROR(__xludf.DUMMYFUNCTION("""COMPUTED_VALUE"""),"iPhone 15, Black, 256GB, Logic Board Assy Mid System, ROW") -> iPhone 15, Black, 256GB, Logic Board Assy Mid System, ROW | I14: =IFERROR(__xludf.DUMMYFUNCTION("""COMPUTED_VALUE"""),9.0) -> 9 | K14: =IFERROR(__xludf.DUMMYFUNCTION("""COMPUTED_VALUE"""),"MOBILECARE - APP THE ANNEX") -> MOBILECARE - APP THE ANNEX | L14: =IFERROR(__xludf.DUMMYFUNCTION("""COMPUTED_VALUE"""),5.0) -> 5 | Z14: =IFERROR(__xludf.DUMMYFUNCTION("""COMPUTED_VALUE"""),"MOBILECARE - S'MAISON") -> MOBILECARE - S'MAISON | AA14: =IFERROR(__xludf.DUMMYFUNCTION("""COMPUTED_VALUE"""),3.0) -> 3
A15: =TEXT(B15:B1012,"MMMM") -> January | B15: =IFERROR(__xludf.DUMMYFUNCTION("""COMPUTED_VALUE"""),46052.0) -> 46052 | C15: =IFERROR(__xludf.DUMMYFUNCTION("""COMPUTED_VALUE"""),"MOBILECARE - DAVAO") -> MOBILECARE - DAVAO | D15: =IFERROR(__xludf.DUMMYFUNCTION("""COMPUTED_VALUE"""),"PP661-28868") -> PP661-28868 | E15: =IFERROR(__xludf.DUMMYFUNCTION("""COMPUTED_VALUE"""),"iPhone 14, Midnight, 128GB, Logic Board Assy Mid System, ROW") -> iPhone 14, Midnight, 128GB, Logic Board Assy Mid System, ROW | G15: =IFERROR(__xludf.DUMMYFUNCTION("""COMPUTED_VALUE"""),"TA661-36697") -> TA661-36697 | H15: =IFERROR(__xludf.DUMMYFUNCTION("""COMPUTED_VALUE"""),"iPhone 15, Pink, 256GB, Logic Board Assy Mid System, ROW") -> iPhone 15, Pink, 256GB, Logic Board Assy Mid System, ROW | I15: =IFERROR(__xludf.DUMMYFUNCTION("""COMPUTED_VALUE"""),9.0) -> 9 | K15: =IFERROR(__xludf.DUMMYFUNCTION("""COMPUTED_VALUE"""),"MOBILECARE - APP MAGNOLIA") -> MOBILECARE - APP MAGNOLIA | L15: =IFERROR(__xludf.DUMMYFUNCTION("""COMPUTED_VALUE"""),4.0) -> 4 | Z15: =IFERROR(__xludf.DUMMYFUNCTION("""COMPUTED_VALUE"""),"MOBILECARE - ZAMBOANGA") -> MOBILECARE - ZAMBOANGA | AA15: =IFERROR(__xludf.DUMMYFUNCTION("""COMPUTED_VALUE"""),3.0) -> 3
A16: =TEXT(B16:B1013,"MMMM") -> January | B16: =IFERROR(__xludf.DUMMYFUNCTION("""COMPUTED_VALUE"""),46049.0) -> 46049 | C16: =IFERROR(__xludf.DUMMYFUNCTION("""COMPUTED_VALUE"""),"MOBILECARE - DAVAO") -> MOBILECARE - DAVAO | D16: =IFERROR(__xludf.DUMMYFUNCTION("""COMPUTED_VALUE"""),"PP661-23454") -> PP661-23454 | E16: =IFERROR(__xludf.DUMMYFUNCTION("""COMPUTED_VALUE"""),"iPhone 13, Midnight, 128GB, Logic Board Assy Rear System, ROW") -> iPhone 13, Midnight, 128GB, Logic Board Assy Rear System, ROW | G16: =IFERROR(__xludf.DUMMYFUNCTION("""COMPUTED_VALUE"""),"TA661-43609") -> TA661-43609 | H16: =IFERROR(__xludf.DUMMYFUNCTION("""COMPUTED_VALUE"""),"128GB, Teal, ROW, iPhone 16, Logic Board Assy Mid System") -> 128GB, Teal, ROW, iPhone 16, Logic Board Assy Mid System | I16: =IFERROR(__xludf.DUMMYFUNCTION("""COMPUTED_VALUE"""),8.0) -> 8 | K16: =IFERROR(__xludf.DUMMYFUNCTION("""COMPUTED_VALUE"""),"MOBILECARE - APP SM LANANG") -> MOBILECARE - APP SM LANANG | L16: =IFERROR(__xludf.DUMMYFUNCTION("""COMPUTED_VALUE"""),4.0) -> 4 | Z16: =IFERROR(__xludf.DUMMYFUNCTION("""COMPUTED_VALUE"""),"MOBILECARE - APP MALL OF ASIA") -> MOBILECARE - APP MALL OF ASIA | AA16: =IFERROR(__xludf.DUMMYFUNCTION("""COMPUTED_VALUE"""),2.0) -> 2
A17: =TEXT(B17:B1014,"MMMM") -> January | B17: =IFERROR(__xludf.DUMMYFUNCTION("""COMPUTED_VALUE"""),46044.0) -> 46044 | C17: =IFERROR(__xludf.DUMMYFUNCTION("""COMPUTED_VALUE"""),"MOBILECARE - DAVAO") -> MOBILECARE - DAVAO | D17: =IFERROR(__xludf.DUMMYFUNCTION("""COMPUTED_VALUE"""),"PP661-23454") -> PP661-23454 | E17: =IFERROR(__xludf.DUMMYFUNCTION("""COMPUTED_VALUE"""),"iPhone 13, Midnight, 128GB, Logic Board Assy Rear System, ROW") -> iPhone 13, Midnight, 128GB, Logic Board Assy Rear System, ROW | G17: =IFERROR(__xludf.DUMMYFUNCTION("""COMPUTED_VALUE"""),"TA661-45232") -> TA661-45232 | H17: =IFERROR(__xludf.DUMMYFUNCTION("""COMPUTED_VALUE"""),"128GB, White, ROW, iPhone 16 Plus, Logic Board Assy Mid System") -> 128GB, White, ROW, iPhone 16 Plus, Logic Board Assy Mid System | I17: =IFERROR(__xludf.DUMMYFUNCTION("""COMPUTED_VALUE"""),8.0) -> 8 | K17: =IFERROR(__xludf.DUMMYFUNCTION("""COMPUTED_VALUE"""),"MOBILECARE - APP FESTIVAL MALL") -> MOBILECARE - APP FESTIVAL MALL | L17: =IFERROR(__xludf.DUMMYFUNCTION("""COMPUTED_VALUE"""),4.0) -> 4 | Z17: =IFERROR(__xludf.DUMMYFUNCTION("""COMPUTED_VALUE"""),"MOBILECARE - CAGAYAN DE ORO") -> MOBILECARE - CAGAYAN DE ORO | AA17: =IFERROR(__xludf.DUMMYFUNCTION("""COMPUTED_VALUE"""),2.0) -> 2
A18: =TEXT(B18:B1015,"MMMM") -> January | B18: =IFERROR(__xludf.DUMMYFUNCTION("""COMPUTED_VALUE"""),46047.0) -> 46047 | C18: =IFERROR(__xludf.DUMMYFUNCTION("""COMPUTED_VALUE"""),"MOBILECARE - DAVAO") -> MOBILECARE - DAVAO | D18: =IFERROR(__xludf.DUMMYFUNCTION("""COMPUTED_VALUE"""),"PP661-23454") -> PP661-23454 | E18: =IFERROR(__xludf.DUMMYFUNCTION("""COMPUTED_VALUE"""),"iPhone 13, Midnight, 128GB, Logic Board Assy Rear System, ROW") -> iPhone 13, Midnight, 128GB, Logic Board Assy Rear System, ROW | G18: =IFERROR(__xludf.DUMMYFUNCTION("""COMPUTED_VALUE"""),"TA661-43608") -> TA661-43608 | H18: =IFERROR(__xludf.DUMMYFUNCTION("""COMPUTED_VALUE"""),"128GB, Ultramarine, ROW, iPhone 16, Logic Board Assy Mid System") -> 128GB, Ultramarine, ROW, iPhone 16, Logic Board Assy Mid System | I18: =IFERROR(__xludf.DUMMYFUNCTION("""COMPUTED_VALUE"""),6.0) -> 6 | K18: =IFERROR(__xludf.DUMMYFUNCTION("""COMPUTED_VALUE"""),"MOBILECARE - APP TRINOMA") -> MOBILECARE - APP TRINOMA | L18: =IFERROR(__xludf.DUMMYFUNCTION("""COMPUTED_VALUE"""),4.0) -> 4 | Z18: =IFERROR(__xludf.DUMMYFUNCTION("""COMPUTED_VALUE"""),"MOBILECARE - CEBU") -> MOBILECARE - CEBU | AA18: =IFERROR(__xludf.DUMMYFUNCTION("""COMPUTED_VALUE"""),2.0) -> 2
A19: =TEXT(B19:B1016,"MMMM") -> January | B19: =IFERROR(__xludf.DUMMYFUNCTION("""COMPUTED_VALUE"""),46046.0) -> 46046 | C19: =IFERROR(__xludf.DUMMYFUNCTION("""COMPUTED_VALUE"""),"MOBILECARE - DAVAO") -> MOBILECARE - DAVAO | D19: =IFERROR(__xludf.DUMMYFUNCTION("""COMPUTED_VALUE"""),"TA661-43609") -> TA661-43609 | E19: =IFERROR(__xludf.DUMMYFUNCTION("""COMPUTED_VALUE"""),"128GB, Teal, ROW, iPhone 16, Logic Board Assy Mid System") -> 128GB, Teal, ROW, iPhone 16, Logic Board Assy Mid System | G19: =IFERROR(__xludf.DUMMYFUNCTION("""COMPUTED_VALUE"""),"TA661-36695") -> TA661-36695 | H19: =IFERROR(__xludf.DUMMYFUNCTION("""COMPUTED_VALUE"""),"iPhone 15, Green, 128GB, Logic Board Assy Mid System, ROW") -> iPhone 15, Green, 128GB, Logic Board Assy Mid System, ROW | I19: =IFERROR(__xludf.DUMMYFUNCTION("""COMPUTED_VALUE"""),6.0) -> 6 | K19: =IFERROR(__xludf.DUMMYFUNCTION("""COMPUTED_VALUE"""),"MOBILECARE - S'MAISON") -> MOBILECARE - S'MAISON | L19: =IFERROR(__xludf.DUMMYFUNCTION("""COMPUTED_VALUE"""),3.0) -> 3 | Z19: =IFERROR(__xludf.DUMMYFUNCTION("""COMPUTED_VALUE"""),"MOBILECARE - APP GREENBELT 3") -> MOBILECARE - APP GREENBELT 3 | AA19: =IFERROR(__xludf.DUMMYFUNCTION("""COMPUTED_VALUE"""),1.0) -> 1
A20: =TEXT(B20:B1017,"MMMM") -> January | B20: =IFERROR(__xludf.DUMMYFUNCTION("""COMPUTED_VALUE"""),46040.0) -> 46040 | C20: =IFERROR(__xludf.DUMMYFUNCTION("""COMPUTED_VALUE"""),"MOBILECARE - DAVAO") -> MOBILECARE - DAVAO | D20: =IFERROR(__xludf.DUMMYFUNCTION("""COMPUTED_VALUE"""),"TA661-36694") -> TA661-36694 | E20: =IFERROR(__xludf.DUMMYFUNCTION("""COMPUTED_VALUE"""),"iPhone 15, Blue, 128GB, Logic Board Assy Mid System, ROW") -> iPhone 15, Blue, 128GB, Logic Board Assy Mid System, ROW | G20: =IFERROR(__xludf.DUMMYFUNCTION("""COMPUTED_VALUE"""),"TA661-43607") -> TA661-43607 | H20: =IFERROR(__xludf.DUMMYFUNCTION("""COMPUTED_VALUE"""),"128GB, Pink, ROW, iPhone 16, Logic Board Assy Mid System") -> 128GB, Pink, ROW, iPhone 16, Logic Board Assy Mid System | I20: =IFERROR(__xludf.DUMMYFUNCTION("""COMPUTED_VALUE"""),6.0) -> 6 | K20: =IFERROR(__xludf.DUMMYFUNCTION("""COMPUTED_VALUE"""),"MOBILECARE - NORTHEAST SQUARE") -> MOBILECARE - NORTHEAST SQUARE | L20: =IFERROR(__xludf.DUMMYFUNCTION("""COMPUTED_VALUE"""),3.0) -> 3 | Z20: =IFERROR(__xludf.DUMMYFUNCTION("""COMPUTED_VALUE"""),"MOBILECARE - APP MEGAMALL") -> MOBILECARE - APP MEGAMALL | AA20: =IFERROR(__xludf.DUMMYFUNCTION("""COMPUTED_VALUE"""),1.0) -> 1
A21: =TEXT(B21:B1018,"MMMM") -> January | B21: =IFERROR(__xludf.DUMMYFUNCTION("""COMPUTED_VALUE"""),46040.0) -> 46040 | C21: =IFERROR(__xludf.DUMMYFUNCTION("""COMPUTED_VALUE"""),"MOBILECARE - DAVAO") -> MOBILECARE - DAVAO | D21: =IFERROR(__xludf.DUMMYFUNCTION("""COMPUTED_VALUE"""),"661-36841") -> 661-36841 | E21: =IFERROR(__xludf.DUMMYFUNCTION("""COMPUTED_VALUE"""),"Blue, Back Glass, iPhone 15") -> Blue, Back Glass, iPhone 15 | G21: =IFERROR(__xludf.DUMMYFUNCTION("""COMPUTED_VALUE"""),"661-56122") -> 661-56122 | H21: =IFERROR(__xludf.DUMMYFUNCTION("""COMPUTED_VALUE"""),"Silver, Back Glass, iPhone 17 Pro") -> Silver, Back Glass, iPhone 17 Pro | I21: =IFERROR(__xludf.DUMMYFUNCTION("""COMPUTED_VALUE"""),6.0) -> 6 | K21: =IFERROR(__xludf.DUMMYFUNCTION("""COMPUTED_VALUE"""),"MOBILECARE - APP MALL OF ASIA") -> MOBILECARE - APP MALL OF ASIA | L21: =IFERROR(__xludf.DUMMYFUNCTION("""COMPUTED_VALUE"""),2.0) -> 2 | Z21: =IFERROR(__xludf.DUMMYFUNCTION("""COMPUTED_VALUE"""),"MOBILECARE - APP POWER PLANT MALL") -> MOBILECARE - APP POWER PLANT MALL | AA21: =IFERROR(__xludf.DUMMYFUNCTION("""COMPUTED_VALUE"""),1.0) -> 1
A22: =TEXT(B22:B1019,"MMMM") -> January | B22: =IFERROR(__xludf.DUMMYFUNCTION("""COMPUTED_VALUE"""),46045.0) -> 46045 | C22: =IFERROR(__xludf.DUMMYFUNCTION("""COMPUTED_VALUE"""),"MOBILECARE - DAVAO") -> MOBILECARE - DAVAO | D22: =IFERROR(__xludf.DUMMYFUNCTION("""COMPUTED_VALUE"""),"PP661-23454") -> PP661-23454 | E22: =IFERROR(__xludf.DUMMYFUNCTION("""COMPUTED_VALUE"""),"iPhone 13, Midnight, 128GB, Logic Board Assy Rear System, ROW") -> iPhone 13, Midnight, 128GB, Logic Board Assy Rear System, ROW | G22: =IFERROR(__xludf.DUMMYFUNCTION("""COMPUTED_VALUE"""),"TA661-44995") -> TA661-44995 | H22: =IFERROR(__xludf.DUMMYFUNCTION("""COMPUTED_VALUE"""),"128GB, Black Titanium, ROW, iPhone 16 Pro, Logic Board Assy Mid System") -> 128GB, Black Titanium, ROW, iPhone 16 Pro, Logic Board Assy Mid System | I22: =IFERROR(__xludf.DUMMYFUNCTION("""COMPUTED_VALUE"""),6.0) -> 6 | K22: =IFERROR(__xludf.DUMMYFUNCTION("""COMPUTED_VALUE"""),"MOBILECARE - APP MEGAMALL") -> MOBILECARE - APP MEGAMALL | L22: =IFERROR(__xludf.DUMMYFUNCTION("""COMPUTED_VALUE"""),1.0) -> 1 | Z22: =IFERROR(__xludf.DUMMYFUNCTION("""COMPUTED_VALUE"""),"MOBILECARE - FESTIVE WALK ILOILO") -> MOBILECARE - FESTIVE WALK ILOILO | AA22: =IFERROR(__xludf.DUMMYFUNCTION("""COMPUTED_VALUE"""),1.0) -> 1
A23: =TEXT(B23:B1020,"MMMM") -> January | B23: =IFERROR(__xludf.DUMMYFUNCTION("""COMPUTED_VALUE"""),46044.0) -> 46044 | C23: =IFERROR(__xludf.DUMMYFUNCTION("""COMPUTED_VALUE"""),"MOBILECARE - DAVAO") -> MOBILECARE - DAVAO | D23: =IFERROR(__xludf.DUMMYFUNCTION("""COMPUTED_VALUE"""),"PP661-23455") -> PP661-23455 | E23: =IFERROR(__xludf.DUMMYFUNCTION("""COMPUTED_VALUE"""),"iPhone 13, Starlight, 128GB, Logic Board Assy Rear System, ROW") -> iPhone 13, Starlight, 128GB, Logic Board Assy Rear System, ROW | G23: =IFERROR(__xludf.DUMMYFUNCTION("""COMPUTED_VALUE"""),"TA661-44997") -> TA661-44997 | H23: =IFERROR(__xludf.DUMMYFUNCTION("""COMPUTED_VALUE"""),"128GB, Desert Titanium, ROW, iPhone 16 Pro, Logic Board Assy Mid System") -> 128GB, Desert Titanium, ROW, iPhone 16 Pro, Logic Board Assy Mid System | I23: =IFERROR(__xludf.DUMMYFUNCTION("""COMPUTED_VALUE"""),6.0) -> 6 | K23: =IFERROR(__xludf.DUMMYFUNCTION("""COMPUTED_VALUE"""),"MOBILECARE - APP GREENBELT 3") -> MOBILECARE - APP GREENBELT 3 | L23: =IFERROR(__xludf.DUMMYFUNCTION("""COMPUTED_VALUE"""),1.0) -> 1 | Z23: =IFERROR(__xludf.DUMMYFUNCTION("""COMPUTED_VALUE"""),"MOBILECARE - NAGA") -> MOBILECARE - NAGA | AA23: =IFERROR(__xludf.DUMMYFUNCTION("""COMPUTED_VALUE"""),1.0) -> 1
A24: =TEXT(B24:B1021,"MMMM") -> January | B24: =IFERROR(__xludf.DUMMYFUNCTION("""COMPUTED_VALUE"""),46039.0) -> 46039 | C24: =IFERROR(__xludf.DUMMYFUNCTION("""COMPUTED_VALUE"""),"MOBILECARE - DAVAO") -> MOBILECARE - DAVAO | D24: =IFERROR(__xludf.DUMMYFUNCTION("""COMPUTED_VALUE"""),"PP661-23454") -> PP661-23454 | E24: =IFERROR(__xludf.DUMMYFUNCTION("""COMPUTED_VALUE"""),"iPhone 13, Midnight, 128GB, Logic Board Assy Rear System, ROW") -> iPhone 13, Midnight, 128GB, Logic Board Assy Rear System, ROW | G24: =IFERROR(__xludf.DUMMYFUNCTION("""COMPUTED_VALUE"""),"TA661-44999") -> TA661-44999 | H24: =IFERROR(__xludf.DUMMYFUNCTION("""COMPUTED_VALUE"""),"256GB, Black Titanium, ROW, iPhone 16 Pro, Logic Board Assy Mid System") -> 256GB, Black Titanium, ROW, iPhone 16 Pro, Logic Board Assy Mid System | I24: =IFERROR(__xludf.DUMMYFUNCTION("""COMPUTED_VALUE"""),5.0) -> 5 | K24: =IFERROR(__xludf.DUMMYFUNCTION("""COMPUTED_VALUE"""),"MOBILECARE - THE PODIUM") -> MOBILECARE - THE PODIUM | L24: =IFERROR(__xludf.DUMMYFUNCTION("""COMPUTED_VALUE"""),1.0) -> 1 | Z24: =IFERROR(__xludf.DUMMYFUNCTION("""COMPUTED_VALUE"""),"MOBILECARE - THE PODIUM") -> MOBILECARE - THE PODIUM | AA24: =IFERROR(__xludf.DUMMYFUNCTION("""COMPUTED_VALUE"""),1.0) -> 1
A25: =TEXT(B25:B1022,"MMMM") -> January | B25: =IFERROR(__xludf.DUMMYFUNCTION("""COMPUTED_VALUE"""),46037.0) -> 46037 | C25: =IFERROR(__xludf.DUMMYFUNCTION("""COMPUTED_VALUE"""),"MOBILECARE - DAVAO") -> MOBILECARE - DAVAO | D25: =IFERROR(__xludf.DUMMYFUNCTION("""COMPUTED_VALUE"""),"PP661-23455") -> PP661-23455 | E25: =IFERROR(__xludf.DUMMYFUNCTION("""COMPUTED_VALUE"""),"iPhone 13, Starlight, 128GB, Logic Board Assy Rear System, ROW") -> iPhone 13, Starlight, 128GB, Logic Board Assy Rear System, ROW | G25: =IFERROR(__xludf.DUMMYFUNCTION("""COMPUTED_VALUE"""),"PP661-28873") -> PP661-28873 | H25: =IFERROR(__xludf.DUMMYFUNCTION("""COMPUTED_VALUE"""),"iPhone 14, Midnight, 256GB, Logic Board Assy Mid System, ROW") -> iPhone 14, Midnight, 256GB, Logic Board Assy Mid System, ROW | I25: =IFERROR(__xludf.DUMMYFUNCTION("""COMPUTED_VALUE"""),5.0) -> 5 | K25: =IFERROR(__xludf.DUMMYFUNCTION("""COMPUTED_VALUE"""),"MOBILECARE - APP POWER PLANT MALL") -> MOBILECARE - APP POWER PLANT MALL | L25: =IFERROR(__xludf.DUMMYFUNCTION("""COMPUTED_VALUE"""),1.0) -> 1
A26: =TEXT(B26:B1023,"MMMM") -> January | B26: =IFERROR(__xludf.DUMMYFUNCTION("""COMPUTED_VALUE"""),46039.0) -> 46039 | C26: =IFERROR(__xludf.DUMMYFUNCTION("""COMPUTED_VALUE"""),"MOBILECARE - DAVAO") -> MOBILECARE - DAVAO | D26: =IFERROR(__xludf.DUMMYFUNCTION("""COMPUTED_VALUE"""),"TA661-36694") -> TA661-36694 | E26: =IFERROR(__xludf.DUMMYFUNCTION("""COMPUTED_VALUE"""),"iPhone 15, Blue, 128GB, Logic Board Assy Mid System, ROW") -> iPhone 15, Blue, 128GB, Logic Board Assy Mid System, ROW | G26: =IFERROR(__xludf.DUMMYFUNCTION("""COMPUTED_VALUE"""),"TA661-45236") -> TA661-45236 | H26: =IFERROR(__xludf.DUMMYFUNCTION("""COMPUTED_VALUE"""),"256GB, Black, ROW, iPhone 16 Plus, Logic Board Assy Mid System") -> 256GB, Black, ROW, iPhone 16 Plus, Logic Board Assy Mid System | I26: =IFERROR(__xludf.DUMMYFUNCTION("""COMPUTED_VALUE"""),5.0) -> 5 | O26: Part Number | P26: Part Description | Q26: Quantity | Y26: Part Number | Z26: Part Description | AA26: Quantity
